<mujoco model="spaceroverMCL">
  <compiler angle="radian" meshdir="assets/meshes/" />

  <option timestep="0.001" integrator="RK4" gravity = "0 0 -1.67" cone="elliptic" impratio="100">
    <flag sensornoise="enable" energy="enable" contact="enable" />
  </option>


  <default>
    <default class="spaceroverMCL">
      <geom friction="0.6" margin="0.001" condim="1"/>
      <joint axis="0 0 -1" armature="0.01" damping="2" stiffness="0" frictionloss="1"/>

      <default class="sus_joint">
        <joint range="-1.0472 1.0472"/>
      </default>

      <default class="steer_joint">
        <joint range="-1.0472 1.0472"/>
      </default>

      <default class="visual">
        <geom type="mesh" contype="0" conaffinity="0" group="2"/>
      </default>

      <default class= "collision">
        <geom group="3" priority="1" solimp="0.015 1 0.031" condim="6" friction="0.8 0.02 0.05"/>
      </default>

      <default class="Tire">
        <geom group="4" priority="1" solimp="0.015 1 0.031" condim="6" friction="0.773 0.02 0.2"/>
      </default>


    </default>
  </default>




  <asset>
    <mesh name="trunk" file="base_link.STL"/>
    <mesh name="FL_bot_sus_bar" file="FL_bot_sus_bar.STL"/>
    <mesh name="FL_sus_cover" file="FL_sus_cover.STL"/>
    <mesh name="FL_steer_link" file="FL_steer_link.STL"/>
    <mesh name="FL_wheel" file="FL_wheel.STL"/>
    <mesh name="FR_bot_sus_bar" file="FR_bot_sus_bar.STL"/>
    <mesh name="FR_sus_cover" file="FR_sus_cover.STL"/>
    <mesh name="FR_steer_link" file="FR_steer_link.STL"/>
    <mesh name="FR_wheel" file="FR_wheel.STL"/>
    <mesh name="RL_bot_sus_bar" file="RL_bot_sus_bar.STL"/>
    <mesh name="RL_sus_cover" file="RL_sus_cover.STL"/>
    <mesh name="RL_steer_link" file="RL_steer_link.STL"/>
    <mesh name="RL_wheel" file="RL_wheel.STL"/>
    <mesh name="RR_bot_sus_bar" file="RR_bot_sus_bar.STL"/>
    <mesh name="RR_sus_cover" file="RR_sus_cover.STL"/>
    <mesh name="RR_steer_link" file="RR_steer_link.STL"/>
    <mesh name="RR_wheel" file="RR_wheel.STL"/>

    <texture name="Dgist" type="2d" file="Dgist_Logo.png"/>
    <texture name="Mcl" type="2d" file="Mcl_Logo.png"/>
    <texture name="Car_num" type="2d" file="Car_num.png"/>

    <material name="Dgist_Mark" texture="Dgist" reflectance="0.2" shininess="0.1"/>
    <material name="Mcl_Mark" texture="Mcl" reflectance="0.2" shininess="0.1"/>
    <material name="Car_num_Mark" texture="Car_num" reflectance="0.2" shininess="0.1"/>


  </asset>


  <worldbody>
    <light diffuse=".5 .5 .5" pos="0 0 3" dir="0 0 -1"/>
    <body name="trunk" pos="0 0 0" euler="0 0 0">
      <inertial pos="-1.7694E-15 -6.6613E-16 0.076193" euler="0 0 0" mass="94" diaginertia="4.1052 12.572 15.42"/>
      <freejoint/>
      <site type="box" name="imu" pos="0 0 0.05" size="0.1 0.05 0.05" rgba="0 0 1 1" />
      <geom class="visual" mesh="trunk" rgba="0.7373 0.4196 0 1" />
      <geom class="visual" type="box" pos="0.24735 0.255 0.13" size="0.18 0.12 0.00000001" euler="1.571 3.1416 0" material="Dgist_Mark" />
      <geom class="visual" type="box" pos="-0.24735 0.255 0.13" size="0.2 0.12 0.00000001" euler="1.571 3.1416 0" material="Mcl_Mark" />

      <geom type="box" pos="0 0 0.1" size="0.525 0.25 0.1" class="collision"/>

      <body name="FL_bot_sus_bar" pos="0.54 0.21 0.04" quat="0.5 -0.5 0.5 -0.5">
        <inertial pos="-0.08 -0.025 0.005" quat="0 0.707107 0 0.707107" mass="5.56431" diaginertia="0.0136372 0.0129398 0.000906033"/>
        <joint name="FL_sus_act" pos="0 0 0" axis="0 0 1"/>
        <geom class="visual" rgba="0.7373 0.4196 0 1" mesh="FL_bot_sus_bar"/>
        <geom type="capsule" pos="-0.06 0 0.015" euler="0 1.5708 0" size="0.02 0.09" class="collision"/>

        <body name="FL_sus_cover" pos="-0.16 0 0.005">
          <inertial pos="-0.0184682 -0.025 -0.00192197" quat="0.5 0.5 -0.5 0.5" mass="1.7057" diaginertia="0.000625818 0.000586045 0.00016883"/>
          <joint name="FL_sus_link_joint" pos="0 0 0" axis="0 0 1"/>
          <geom class="visual" rgba="0.7373 0.4196 0 1" mesh="FL_sus_cover"/>

          <body name="FL_steer_link" pos="-0.03 0 0" quat="0.707107 0.707107 0 0">
            <inertial pos="-0.0239659 -2.29029e-09 -0.0410337" quat="0.581915 0.401715 0.401715 0.581915" mass="2.73012" diaginertia="0.00282515 0.00245109 0.000681196"/>
            <joint name="FL_steer_rev" pos="0 0 0" axis="0 0 1"/>
            <geom class="visual" rgba="0.7373 0.4196 0 1" mesh="FL_steer_link"/>
            <geom type="cylinder" pos="0.00001 0 -0.001" size="0.015 0.06" class="collision"/>

            <body name="FL_wheel" pos="-0.08 0 -0.05" quat="0 -0.707107 0 0.707107">
              <inertial pos="0 0 0.0824387" quat="0.5 0.5 -0.5 0.5" mass="5.00004" diaginertia="0.0656933 0.0388687 0.0388687"/>
              <joint name="FL_drive_act" pos="0 0 0" axis="0 0 1"/>
              <geom class="visual" rgba="0. 0. 0. 1" mesh="FL_wheel"/>
              <geom type="ellipsoid" pos="0 0 0.0823537" size="0.15 0.15 0.06" class="Tire" />

              <site type="cylinder" name="end_point_FL" pos="0 0 0.0823537" euler="0 0 0.6981" size="0.15 0.06" rgba="0 0 1 0" />

            </body>
          </body>
        </body>
      </body>

      <body name="FR_bot_sus_bar" pos="0.54 -0.21 0.04" quat="0.5 -0.5 0.5 -0.5">
        <inertial pos="0.08 -0.025 0.005" quat="0 0.707107 0 0.707107" mass="5.56431" diaginertia="0.0136372 0.0129398 0.000906033"/>
        <joint name="FR_sus_act" pos="0 0 0" axis="0 0 -1"/>
        <geom class="visual" rgba="0.7373 0.4196 0 1" mesh="FR_bot_sus_bar"/>
        <geom type="capsule" pos="0.06 0 0.015" euler="0 1.5708 0" size="0.02 0.09" class="collision"/>

        <body name="FR_sus_cover" pos="0.16 0 0.005">
          <inertial pos="0.0184682 -0.025 -0.00192197" quat="0.5 0.5 -0.5 0.5" mass="1.7057" diaginertia="0.000625818 0.000586045 0.00016883"/>
          <joint name="FR_sus_link_joint" pos="0 0 0" axis="0 0 -1"/>
          <geom class="visual" rgba="0.7373 0.4196 0 1" mesh="FR_sus_cover"/>

          <body name="FR_steer_link" pos="0.03 0 0" quat="0.707107 0.707107 0 0">
            <inertial pos="0.0239659 2.29029e-09 -0.0410337" quat="0.401715 0.581915 0.581915 0.401715" mass="2.73012" diaginertia="0.00282515 0.00245109 0.000681196"/>
            <joint name="FR_steer_rev" pos="0 0 0" axis="0 0 1"/>
            <geom class="visual" rgba="0.7373 0.4196 0 1" mesh="FR_steer_link"/>
            <geom type="cylinder" pos="0.00001 0 -0.001" size="0.015 0.06" class="collision"/>

            <body name="FR_wheel" pos="0.08 0 -0.05" quat="0.5 -0.5 -0.5 0.5">
              <inertial pos="0 0 -0.0824387" quat="0.5 0.5 -0.5 0.5" mass="5.00004" diaginertia="0.0656933 0.0388687 0.0388687"/>
              <joint name="FR_drive_act" pos="0 0 0" axis="0 0 1"/>
              <geom class="visual" rgba="0. 0. 0. 1" mesh="FR_wheel"/>
              <geom type="ellipsoid" pos="0 0 -0.0823537" size="0.15 0.15 0.06" class="Tire"/>


              <site type="cylinder" name="end_point_FR" pos="0 0 -0.0823537" size="0.15 0.06" rgba="0 0 1 0" />

            </body>
          </body>
        </body>
      </body>

      <body name="RL_bot_sus_bar" pos="-0.54 0.21 0.04" quat="0.5 -0.5 0.5 -0.5">
        <inertial pos="-0.08 -0.025 -0.005" quat="0 0.707107 0 0.707107" mass="5.56431" diaginertia="0.0136372 0.0129398 0.000906033"/>
        <joint name="RL_sus_act" pos="0 0 0" axis="0 0 1"/>
        <geom class="visual" rgba="0.7373 0.4196 0 1" mesh="RL_bot_sus_bar"/>
        <geom type="capsule" pos="-0.06 0 -0.015" euler="0 1.5708 0" size="0.02 0.09" class="collision"/>


        <body name="RL_sus_cover" pos="-0.16 0 -0.005">
          <inertial pos="-0.0184682 -0.025 0.00192197" quat="0.5 0.5 -0.5 0.5" mass="1.7057" diaginertia="0.000625818 0.000586045 0.00016883"/>
          <joint name="RL_sus_link_joint" pos="0 0 0" axis="0 0 1"/>
          <geom type="mesh" rgba="0.7373 0.4196 0 1" mesh="RL_sus_cover"/>

          <body name="RL_steer_link" pos="-0.03 0 0" quat="0.707107 0.707107 0 0">
            <inertial pos="-0.0239659 -2.29029e-09 -0.0410337" quat="0.581915 0.401715 0.401715 0.581915" mass="2.73012" diaginertia="0.00282515 0.00245109 0.000681196"/>
            <joint name="RL_steer_rev" pos="0 0 0" axis="0 0 1"/>
            <geom class="visual" rgba="0.7373 0.4196 0 1" mesh="RL_steer_link"/>
            <geom type="cylinder" pos="0.00001 0 -0.001" size="0.015 0.06" class="collision"/>


            <body name="RL_wheel" pos="-0.08 0 -0.05" quat="0 -0.707107 0 0.707107">
              <inertial pos="0 0 0.0824387" quat="0.5 0.5 -0.5 0.5" mass="5.00004" diaginertia="0.0656933 0.0388687 0.0388687"/>
              <joint name="RL_drive_act" pos="0 0 0" axis="0 0 1"/>
              <geom class="visual" rgba="0. 0. 0. 1" mesh="RL_wheel"/>
              <geom type="ellipsoid" pos="0 0 0.0823537" size="0.15 0.15 0.06" class="Tire"/>

              <site type="cylinder" name="end_point_RL" pos="0 0 0.0823537" size="0.15 0.06" rgba="0 0 1 0" />

            </body>
          </body>
        </body>
      </body>

      <body name="RR_bot_sus_bar" pos="-0.54 -0.21 0.04" quat="0.5 -0.5 0.5 -0.5">
        <inertial pos="0.08 -0.025 -0.005" quat="0 0.707107 0 0.707107" mass="5.56431" diaginertia="0.0136372 0.0129398 0.000906033"/>
        <joint name="RR_sus_act" pos="0 0 0" axis="0 0 -1"/>
        <geom class="visual" rgba="0.7373 0.4196 0 1" mesh="RR_bot_sus_bar"/>
        <geom type="capsule" pos="0.06 0 -0.015" euler="0 1.5708 0" size="0.02 0.09" class="collision"/>

        <body name="RR_sus_cover" pos="0.16 0 -0.005">
          <inertial pos="0.0184682 -0.025 0.00192197" quat="0.5 0.5 -0.5 0.5" mass="1.7057" diaginertia="0.000625818 0.000586045 0.00016883"/>
          <joint name="RR_sus_link_joint" pos="0 0 0" axis="0 0 -1"/>
          <geom class="visual" rgba="0.7373 0.4196 0 1" mesh="RR_sus_cover"/>

          <body name="RR_steer_link" pos="0.03 0 0" quat="0.707107 0.707107 0 0">
            <inertial pos="0.0239659 2.29029e-09 -0.0410337" quat="0.401715 0.581915 0.581915 0.401715" mass="2.73012" diaginertia="0.00282515 0.00245109 0.000681196"/>

            <joint name="RR_steer_rev" pos="0 0 0" axis="0 0 1"/>
            <geom class="visual" rgba="0.7373 0.4196 0 1" mesh="RR_steer_link"/>
            <geom type="cylinder" pos="0.00001 0 -0.001" size="0.015 0.06" class="collision"/>


            <body name="RR_wheel" pos="0.08 0 -0.05" quat="0.5 0.5 -0.5 -0.5">
              <inertial pos="0 0 -0.0824387" quat="0.5 0.5 -0.5 0.5" mass="5.00004" diaginertia="0.0656933 0.0388687 0.0388687"/>
              <joint name="RR_drive_act" pos="0 0 0" axis="0 0 1"/>
              <geom class="visual" rgba="0. 0. 0. 1" mesh="RR_wheel"/>
              <geom type="ellipsoid" pos="0 0 -0.0823537" size="0.15 0.15 0.06" class="Tire"/>

              <site type="cylinder" name="end_point_RR" pos="0 0 -0.0823537" size="0.15 0.06" rgba="0 0 1 0" />

            </body>
          </body>
        </body>
      </body>
    </body>
  </worldbody>

  <actuator>
    <motor name="FL_sus_motor" joint="FL_sus_act" gear="1" ctrlrange="-100 100" />
    <motor name="FL_cover_motor" joint="FL_sus_link_joint" gear="1" ctrlrange="-100 100" />
    <motor name="FL_steer_motor" joint="FL_steer_rev" gear="1" ctrlrange="-100 100" />
    <motor name="FL_drive_motor" joint="FL_drive_act" gear="1" ctrlrange="-100 100" />

    <motor name="FR_sus_motor" joint="FR_sus_act" gear="1" ctrlrange="-100 100" />
    <motor name="FR_cover_motor" joint="FR_sus_link_joint" gear="1" ctrlrange="-100 100" />
    <motor name="FR_steer_motor" joint="FR_steer_rev" gear="1" ctrlrange="-100 100" />
    <motor name="FR_drive_motor" joint="FR_drive_act" gear="1" ctrlrange="-100 100" />

    <motor name="RL_sus_motor" joint="RL_sus_act" gear="1" ctrlrange="-100 100" />
    <motor name="RL_cover_motor" joint="RL_sus_link_joint" gear="1" ctrlrange="-100 100" />
    <motor name="RL_steer_motor" joint="RL_steer_rev" gear="1" ctrlrange="-100 100" />
    <motor name="RL_drive_motor" joint="RL_drive_act" gear="1" ctrlrange="-100 100" />

    <motor name="RR_sus_motor" joint="RR_sus_act" gear="1" ctrlrange="-100 100" />
    <motor name="RR_cover_motor" joint="RR_sus_link_joint" gear="1" ctrlrange="-100 100" />
    <motor name="RR_steer_motor" joint="RR_steer_rev" gear="1" ctrlrange="-100 100" />
    <motor name="RR_drive_motor" joint="RR_drive_act" gear="1" ctrlrange="-100 100" />
  </actuator>

  <sensor>
    <accelerometer site="imu" name="imu_acc" noise="0.0" />
    <!--0 1 2-->
    <gyro site="imu" name="imu_gyro" noise="0.0" />
    <!--3 4 5-->
    <framelinvel name="trunk_vel" objtype="site" objname="imu" />
    <!--6 7 8-->
    <frameangvel name="trunk_angvel" objtype="site" objname="imu" />
    <!--9 10 11-->
    <framepos name="trunk_pos" objtype="site" objname="imu" />
    <!--12 13 14-->
    <framequat name="trunk_ang" objtype="site" objname="imu" />
    <!--15 16 17 18-->

    <jointpos joint="FL_sus_act" name="ENC_FL_sus" noise="0.0" />
    <jointpos joint="FL_steer_rev" name="ENC_FL_steer" noise="0.0" />
    <jointpos joint="FL_drive_act" name="ENC_FL_drive" noise="0.0" />
    <!--19 20 21-->

    <jointpos joint="FR_sus_act" name="ENC_FR_sus" noise="0.0" />
    <jointpos joint="FR_steer_rev" name="ENC_FR_steer" noise="0.0" />
    <jointpos joint="FR_drive_act" name="ENC_FR_drive" noise="0.0" />
    <!--22 23 24-->

    <jointpos joint="RL_sus_act" name="ENC_RL_sus" noise="0.0" />
    <jointpos joint="RL_steer_rev" name="ENC_RL_steer" noise="0.0" />
    <jointpos joint="RL_drive_act" name="ENC_RL_drive" noise="0.0" />
    <!--25 26 27-->

    <jointpos joint="RR_sus_act" name="ENC_RR_sus" noise="0.0" />
    <jointpos joint="RR_steer_rev" name="ENC_RR_steer" noise="0.0" />
    <jointpos joint="RR_drive_act" name="ENC_RR_drive" noise="0.0" />
    <!--28 29 30-->

    <touch name="touch_sensor_FL" site="end_point_FL" />
    <force name="grf_seonsor_FL" site="end_point_FL" />
    <!--31 32 33 34-->

    <touch name="touch_FR" site="end_point_FR" />
    <force name="grf_seonsor_FR" site="end_point_FR" />
    <!--35 36 37 38-->

    <touch name="touch_RL" site="end_point_RL" />
    <force name="grf_seonsor_RL" site="end_point_RL" />
    <!--39 40 41 42-->

    <touch name="touch_RR" site="end_point_RR" />
    <force name="grf_seonsor_RR" site="end_point_RR" />
    <!--43 44 45 46-->


  </sensor>

  <keyframe>
    <!-- <key name="home" qpos="-4. 5. 0.245 0 0 0 0 0 0 0 0 0 0 0 0 0 0 0 0 0 0 0 0"/> -->
    <key name="home" qpos="0 0 0.15 0 0 0 0 0 0 0 0 0 0 0 0 0 0 0 0 0 0 0 0"/>
  </keyframe>


</mujoco>
